[NbConvertApp] Converting notebook mkstapylton@gmail.com-mattS-qiime2.ipynb to latex
[NbConvertApp] Executing notebook with kernel: jupyter
[NbConvertApp] ERROR | Error while converting 'mkstapylton@gmail.com-mattS-qiime2.ipynb'
Traceback (most recent call last):
  File "/hpc/users/mmedsadmin/.admin_modules/jupyter/lib/python3.9/site-packages/nbconvert/nbconvertapp.py", line 410, in export_single_notebook
    output, resources = self.exporter.from_filename(notebook_filename, resources=resources)
  File "/hpc/users/mmedsadmin/.admin_modules/jupyter/lib/python3.9/site-packages/nbconvert/exporters/exporter.py", line 179, in from_filename
    return self.from_file(f, resources=resources, **kw)
  File "/hpc/users/mmedsadmin/.admin_modules/jupyter/lib/python3.9/site-packages/nbconvert/exporters/exporter.py", line 197, in from_file
    return self.from_notebook_node(nbformat.read(file_stream, as_version=4), resources=resources, **kw)
  File "/hpc/users/mmedsadmin/.admin_modules/jupyter/lib/python3.9/site-packages/nbconvert/exporters/latex.py", line 88, in from_notebook_node
    return super(LatexExporter, self).from_notebook_node(nb, resources, **kw)
  File "/hpc/users/mmedsadmin/.admin_modules/jupyter/lib/python3.9/site-packages/nbconvert/exporters/templateexporter.py", line 307, in from_notebook_node
    nb_copy, resources = super(TemplateExporter, self).from_notebook_node(nb, resources, **kw)
  File "/hpc/users/mmedsadmin/.admin_modules/jupyter/lib/python3.9/site-packages/nbconvert/exporters/exporter.py", line 139, in from_notebook_node
    nb_copy, resources = self._preprocess(nb_copy, resources)
  File "/hpc/users/mmedsadmin/.admin_modules/jupyter/lib/python3.9/site-packages/nbconvert/exporters/exporter.py", line 316, in _preprocess
    nbc, resc = preprocessor(nbc, resc)
  File "/hpc/users/mmedsadmin/.admin_modules/jupyter/lib/python3.9/site-packages/nbconvert/preprocessors/base.py", line 47, in __call__
    return self.preprocess(nb, resources)
  File "/hpc/users/mmedsadmin/.admin_modules/jupyter/lib/python3.9/site-packages/nbconvert/preprocessors/execute.py", line 405, in preprocess
    nb, resources = super(ExecutePreprocessor, self).preprocess(nb, resources)
  File "/hpc/users/mmedsadmin/.admin_modules/jupyter/lib/python3.9/site-packages/nbconvert/preprocessors/base.py", line 69, in preprocess
    nb.cells[index], resources = self.preprocess_cell(cell, resources, index)
  File "/hpc/users/mmedsadmin/.admin_modules/jupyter/lib/python3.9/site-packages/nbconvert/preprocessors/execute.py", line 448, in preprocess_cell
    raise CellExecutionError.from_cell_and_msg(cell, out)
nbconvert.preprocessors.execute.CellExecutionError: An error occurred while executing the following cell:
------------------
df = pd.read_csv('stats.tsv', sep='\t', header=0, skiprows=[1])
data = []
m = 0
# Split rows into five categories
for i in range(len(df['sample-id'])):
    _input = df['input'][i]
    _filtered = df['filtered'][i]
    _denoised = df['denoised'][i]
    _merged = df['merged'][i]
    _nonchimeric = df['non-chimeric'][i]
    # Store maximum
    if _input > m:
        m = _input
    # Order sections so less filtered goes at the top
    data.append([df['sample-id'][i], _input - _filtered, "a"])
    data.append([df['sample-id'][i], _filtered - _denoised, "b"])
    data.append([df['sample-id'][i], _denoised - _merged, "c"])
    data.append([df['sample-id'][i], _merged - _nonchimeric, "d"])
    data.append([df['sample-id'][i], _nonchimeric, "e"])
df = pd.DataFrame(data, columns=['variable', 'value', "type"])
# Set count to number of desired y-axis values-1
count = 5
# Create discrete y-axis values
breaks = pd.Series([int(i*(m/count)) for i in range(count+1)])
------------------

[0;31m---------------------------------------------------------------------------[0m
[0;31mKeyError[0m                                  Traceback (most recent call last)
File [0;32m~/.admin_modules/jupyter/lib/python3.9/site-packages/pandas/core/indexes/base.py:3080[0m, in [0;36mIndex.get_loc[0;34m(self, key, method, tolerance)[0m
[1;32m   3079[0m [38;5;28;01mtry[39;00m:
[0;32m-> 3080[0m     [38;5;28;01mreturn[39;00m [38;5;28;43mself[39;49m[38;5;241;43m.[39;49m[43m_engine[49m[38;5;241;43m.[39;49m[43mget_loc[49m[43m([49m[43mcasted_key[49m[43m)[49m
[1;32m   3081[0m [38;5;28;01mexcept[39;00m [38;5;167;01mKeyError[39;00m [38;5;28;01mas[39;00m err:

File [0;32mpandas/_libs/index.pyx:70[0m, in [0;36mpandas._libs.index.IndexEngine.get_loc[0;34m()[0m

File [0;32mpandas/_libs/index.pyx:101[0m, in [0;36mpandas._libs.index.IndexEngine.get_loc[0;34m()[0m

File [0;32mpandas/_libs/hashtable_class_helper.pxi:4554[0m, in [0;36mpandas._libs.hashtable.PyObjectHashTable.get_item[0;34m()[0m

File [0;32mpandas/_libs/hashtable_class_helper.pxi:4562[0m, in [0;36mpandas._libs.hashtable.PyObjectHashTable.get_item[0;34m()[0m

[0;31mKeyError[0m: 'merged'

The above exception was the direct cause of the following exception:

[0;31mKeyError[0m                                  Traceback (most recent call last)
Input [0;32mIn [4][0m, in [0;36m<cell line: 5>[0;34m()[0m
[1;32m      7[0m _filtered [38;5;241m=[39m df[[38;5;124m'[39m[38;5;124mfiltered[39m[38;5;124m'[39m][i]
[1;32m      8[0m _denoised [38;5;241m=[39m df[[38;5;124m'[39m[38;5;124mdenoised[39m[38;5;124m'[39m][i]
[0;32m----> 9[0m _merged [38;5;241m=[39m [43mdf[49m[43m[[49m[38;5;124;43m'[39;49m[38;5;124;43mmerged[39;49m[38;5;124;43m'[39;49m[43m][49m[i]
[1;32m     10[0m _nonchimeric [38;5;241m=[39m df[[38;5;124m'[39m[38;5;124mnon-chimeric[39m[38;5;124m'[39m][i]
[1;32m     11[0m [38;5;66;03m# Store maximum[39;00m

File [0;32m~/.admin_modules/jupyter/lib/python3.9/site-packages/pandas/core/frame.py:3024[0m, in [0;36mDataFrame.__getitem__[0;34m(self, key)[0m
[1;32m   3022[0m [38;5;28;01mif[39;00m [38;5;28mself[39m[38;5;241m.[39mcolumns[38;5;241m.[39mnlevels [38;5;241m>[39m [38;5;241m1[39m:
[1;32m   3023[0m     [38;5;28;01mreturn[39;00m [38;5;28mself[39m[38;5;241m.[39m_getitem_multilevel(key)
[0;32m-> 3024[0m indexer [38;5;241m=[39m [38;5;28;43mself[39;49m[38;5;241;43m.[39;49m[43mcolumns[49m[38;5;241;43m.[39;49m[43mget_loc[49m[43m([49m[43mkey[49m[43m)[49m
[1;32m   3025[0m [38;5;28;01mif[39;00m is_integer(indexer):
[1;32m   3026[0m     indexer [38;5;241m=[39m [indexer]

File [0;32m~/.admin_modules/jupyter/lib/python3.9/site-packages/pandas/core/indexes/base.py:3082[0m, in [0;36mIndex.get_loc[0;34m(self, key, method, tolerance)[0m
[1;32m   3080[0m         [38;5;28;01mreturn[39;00m [38;5;28mself[39m[38;5;241m.[39m_engine[38;5;241m.[39mget_loc(casted_key)
[1;32m   3081[0m     [38;5;28;01mexcept[39;00m [38;5;167;01mKeyError[39;00m [38;5;28;01mas[39;00m err:
[0;32m-> 3082[0m         [38;5;28;01mraise[39;00m [38;5;167;01mKeyError[39;00m(key) [38;5;28;01mfrom[39;00m [38;5;21;01merr[39;00m
[1;32m   3084[0m [38;5;28;01mif[39;00m tolerance [38;5;129;01mis[39;00m [38;5;129;01mnot[39;00m [38;5;28;01mNone[39;00m:
[1;32m   3085[0m     tolerance [38;5;241m=[39m [38;5;28mself[39m[38;5;241m.[39m_convert_tolerance(tolerance, np[38;5;241m.[39masarray(key))

[0;31mKeyError[0m: 'merged'
KeyError: 'merged'

